<?xml version="1.0"?>
<robot xmlns:xacro="http://www.ros.org/wiki/xacro">
    <xacro:include filename="$(find robotiq_3f_description)/urdf/robotiq_3f_gripper_finger_macro.xacro"/>

    <xacro:macro name="robotiq_3f_gripper"
                 params="prefix:=''
                       use_fake_hardware:=true
                       usb_port:=/dev/ttyUSB0">

        <xacro:robotiq_3f_gripper_finger_articulated prefix="${prefix}finger_b_"/>
        <xacro:robotiq_3f_gripper_finger_articulated prefix="${prefix}finger_a_"/>
        <xacro:robotiq_3f_gripper_finger_articulated prefix="${prefix}finger_c_"/>

        <!-- link list -->
        <link name="${prefix}palm">
            <visual>
                <geometry>
                    <mesh filename="package://robotiq_3f_description/meshes/visual/palm.dae"/>
                </geometry>
                <material name="gray">
                    <color rgba="0.4 0.2 0.2 1"/>
                </material>
            </visual>
            <collision>
                <geometry>
                    <mesh filename="package://robotiq_3f_description/meshes/collision/palm.STL"/>
                </geometry>
                <material name="yellow">
                    <color rgba="0 1 1 1"/>
                </material>
            </collision>
        </link>
        <link name="${prefix}tool0"/>

        <inertial>
            <origin xyz="0 0 0" rpy="0 0 0"/>
            <mass value="1.3"/>
            <inertia ixx="0.006012" ixy="0.000079" ixz="-0.00024" iyy="0.012892" iyz="0" izz="0.002435"/>
        </inertial>
        <!-- end of link list -->
        <!-- joint list -->

        <joint name="${prefix}palm_finger_c_joint" type="revolute">
            <parent link="${prefix}palm"/>
            <child link="${prefix}finger_c_link_0"/>
            <axis xyz="0 1 0"/>
            <origin xyz="-0.0455 0.0214 0.036" rpy="0 3.1416 -1.57"/>
            <limit lower="-0.1784" upper="0.192" effort="100" velocity="100"/>
        </joint>
        <joint name="${prefix}palm_finger_b_joint" type="revolute">
            <parent link="${prefix}palm"/>
            <child link="${prefix}finger_b_link_0"/>
            <axis xyz="0 1 0"/>
            <origin xyz="-0.0455 0.0214 -0.036" rpy="0 3.1416 -1.57"/>
            <limit lower="-0.192" upper="0.1784" effort="100" velocity="100"/>
        </joint>
        <joint name="${prefix}palm_finger_a_joint" type="fixed">
            <parent link="${prefix}palm"/>
            <child link="${prefix}finger_a_link_0"/>
            <axis xyz="0 0 1"/>
            <origin xyz="0.0455 0.0214 0" rpy="0 0 1.57"/>
        </joint>
        <joint name="${prefix}palm_tool0" type="fixed">
            <parent link="${prefix}palm"/>
            <child link="${prefix}tool0"/>
            <origin xyz="0.0 0.0875 0.0" rpy="0 0 1.5707"/>
        </joint>
        <!-- end of joint list -->
    </xacro:macro>
</robot>
