<?xml version="1.0" ?>
<!-- =================================================================================== -->
<!-- |    This document was autogenerated by xacro from /home/mfaroni/projects/arm_robots/src/kuka_iiwa_interface/victor_description/urdf/victor.urdf.xacro | -->
<!-- |    EDITING THIS FILE BY HAND IS NOT RECOMMENDED                                 | -->
<!-- =================================================================================== -->
<robot name="victor">
    <material name="Black">
        <color rgba="0.0 0.0 0.0 1.0" />
    </material>
    <material name="Blue">
        <color rgba="0.0 0.0 0.8 1.0" />
    </material>
    <material name="Green">
        <color rgba="0.0 0.8 0.0 1.0" />
    </material>
    <material name="Grey">
        <color rgba="0.4 0.4 0.4 1.0" />
    </material>
    <material name="Orange">
        <color rgba="1.0 0.4235294117647059 0.0392156862745098 1.0" />
    </material>
    <material name="Brown">
        <color rgba="0.8705882352941177 0.8117647058823529 0.7647058823529411 1.0" />
    </material>
    <material name="Red">
        <color rgba="0.8 0.0 0.0 1.0" />
    </material>
    <material name="White">
        <color rgba="1.0 1.0 1.0 1.0" />
    </material>
    <material name="LightGrey">
        <color rgba="0.7 0.7 0.7 1" />
    </material>
    <material name="DarkGray">
        <color rgba="0.2 0.2 0.2 1" />
    </material>
    <material name="DarkDarkGray">
        <color rgba="0.1 0.1 0.1 1" />
    </material>
    <link name="victor_root" />
    <joint name="victor_dummy_root_joint" type="fixed">
        <parent link="victor_root" />
        <child link="victor_pedestal" />
        <origin rpy="0 0 0" xyz="0 0 0" />
        <axis xyz="0 0 1" />
    </joint>
    <link name="victor_pedestal">
        <visual>
            <origin rpy="0 0 0" xyz="0 0 0.9245" />
            <geometry>
                <mesh filename="package://victor_description/meshes/baxter_pedestal/pedestal_visual.stl" />
            </geometry>
            <material name="DarkGray" />
        </visual>
        <collision>
            <origin rpy="0 0 0" xyz="0 0 0.9245" />
            <geometry>
                <mesh filename="package://victor_description/meshes/baxter_pedestal/pedestal_collision.stl" />
            </geometry>
            <material name="DarkGray" />
        </collision>
        <inertial>
            <origin rpy="0 0 0" xyz="0 0 0" />
            <mass value="60.86397744" />
            <inertia ixx="5.0635929" ixy="0.00103417" ixz="0.80199628" iyy="6.08689388" iyz="0.00105311" izz="4.96191932" />
        </inertial>
    </link>
    <joint name="victor_base_plate_mount_joint" type="fixed">
        <parent link="victor_pedestal" />
        <child link="victor_base_plate_mount" />
        <origin rpy="0 0 0" xyz="0 0 0.863" />
        <axis xyz="0 0 1" />
    </joint>
    <link name="victor_base_plate_mount" />
    <joint name="victor_base_plate_joint" type="fixed">
        <parent link="victor_base_plate_mount" />
        <child link="victor_base_plate" />
        <origin rpy="0 0 0" xyz="0 0 0" />
        <axis xyz="0 0 1" />
    </joint>
    <link name="victor_base_plate">
        <visual>
            <origin rpy="0 0 0" xyz="0 0 0" />
            <geometry>
                <mesh filename="package://victor_description/meshes/torso/torso_visual.stl" />
            </geometry>
            <material name="LightGrey" />
        </visual>
        <collision>
            <origin rpy="0 0 0" xyz="0 0 0.2" />
            <geometry>
                <!--<mesh filename="package://victor_description/meshes/torso_visual_model.stl"/>-->
                <cylinder length="0.7" radius="0.2" />
            </geometry>
            <material name="LightGrey" />
        </collision>
        <inertial>
            <mass value="0.1" />
            <origin xyz="0 0 0" rpy="0 0 0" />
            <inertia ixx="0.03" iyy="0.03" izz="0.03" ixy="0.0" ixz="0.0" iyz="0.0" />
        </inertial>
    </link>
    <joint name="victor_left_arm_mount_joint" type="fixed">
        <parent link="victor_base_plate" />
        <child link="victor_left_arm_mount" />
        <origin rpy="-1.5707963268 0 -0.785398163397448" xyz="-0.02 0.1384885 0.385" />
        <axis xyz="0 0 1" />
    </joint>
    <link name="victor_left_arm_mount">
        <collision>
            <origin rpy="0 0 0" xyz="0 0 -0.013" />
            <geometry>
                <!--<mesh filename="package://victor_description/meshes/torso_visual_model.stl"/>-->
                <box size="0.31 0.31 0.032" />
            </geometry>
            <material name="LightGrey" />
        </collision>
        <inertial>
            <mass value="0.1" />
            <origin xyz="0 0 0" rpy="0 0 0" />
            <inertia ixx="0.03" iyy="0.03" izz="0.03" ixy="0.0" ixz="0.0" iyz="0.0" />
        </inertial>
    </link>
    <joint name="victor_right_arm_mount_joint" type="fixed">
        <parent link="victor_base_plate" />
        <child link="victor_right_arm_mount" />
        <origin rpy="1.5707963268 0 0.785398163397448" xyz="-0.02 -0.1384885 0.385" />
        <axis xyz="0 0 1" />
    </joint>
    <link name="victor_right_arm_mount">
        <collision>
            <origin rpy="0 0 0" xyz="0 0 -0.013" />
            <geometry>
                <!--<mesh filename="package://victor_description/meshes/torso_visual_model.stl"/>-->
                <box size="0.31 0.31 0.032" />
            </geometry>
            <material name="LightGrey" />
        </collision>
        <inertial>
            <mass value="0.1" />
            <origin xyz="0 0 0" rpy="0 0 0" />
            <inertia ixx="0.03" iyy="0.03" izz="0.03" ixy="0.0" ixz="0.0" iyz="0.0" />
        </inertial>
    </link>
    <!--joint between {parent} and link_0-->
    <joint name="victor_left_arm_mount_victor_left_arm_joint" type="fixed">
        <origin rpy="0 0 0" xyz="0 0 0" />
        <parent link="victor_left_arm_mount" />
        <child link="victor_left_arm_link_0" />
    </joint>
    <link name="victor_left_arm_link_0">
        <inertial>
            <origin rpy="0 0 0" xyz="-0.1 0 0.07" />
            <mass value="5" />
            <inertia ixx="0.05" ixy="0" ixz="0" iyy="0.06" iyz="0" izz="0.03" />
        </inertial>
        <visual>
            <origin rpy="0 0 0" xyz="0 0 0" />
            <geometry>
                <mesh filename="package://victor_description/meshes/iiwa7/visual/link_0.stl" />
            </geometry>
            <material name="Grey" />
        </visual>
        <collision>
            <origin rpy="0 0 0" xyz="0 0 0" />
            <geometry>
                <mesh filename="package://victor_description/meshes/iiwa7/collision/link_0.stl" />
            </geometry>
            <material name="Grey" />
        </collision>
        <self_collision_checking>
            <origin rpy="0 0 0" xyz="0 0 0" />
            <geometry>
                <capsule length="0.25" radius="0.15" />
            </geometry>
        </self_collision_checking>
    </link>
    <!-- joint between link_0 and link_1 -->
    <joint name="victor_left_arm_joint_1" type="revolute">
        <parent link="victor_left_arm_link_0" />
        <child link="victor_left_arm_link_1" />
        <origin rpy="0 0 0" xyz="0 0 0.15" />
        <axis xyz="0 0 1" />
        <limit effort="300" lower="-2.9670597283903604" upper="2.9670597283903604" velocity="1.7453292519943295" />
        <dynamics damping="0.5" />
    </joint>
    <link name="victor_left_arm_link_1">
        <inertial>
            <origin rpy="0 0 0" xyz="0 -0.03 0.12" />
            <mass value="3.4525" />
            <inertia ixx="0.02183" ixy="0" ixz="0" iyy="0.007703" iyz="-0.003887" izz="0.02083" />
        </inertial>
        <visual>
            <origin rpy="0 0 0" xyz="0 0 0.0075" />
            <geometry>
                <mesh filename="package://victor_description/meshes/iiwa7/visual/link_1.stl" />
            </geometry>
            <material name="Orange" />
        </visual>
        <collision>
            <origin rpy="0 0 0" xyz="0 0 0.0075" />
            <geometry>
                <mesh filename="package://victor_description/meshes/iiwa7/collision/link_1.stl" />
            </geometry>
            <material name="Orange" />
        </collision>
    </link>
    <joint name="victor_left_arm_joint_2" type="revolute">
        <parent link="victor_left_arm_link_1" />
        <child link="victor_left_arm_link_2" />
        <origin rpy="1.5707963267948966   0 3.141592653589793" xyz="0 0 0.19" />
        <axis xyz="0 0 1" />
        <limit effort="300" lower="-2.0943951023931953" upper="2.0943951023931953" velocity="1.7453292519943295" />
        <dynamics damping="0.5" />
    </joint>
    <link name="victor_left_arm_link_2">
        <inertial>
            <origin rpy="0 0 0" xyz="0.0003 0.059 0.042" />
            <mass value="3.4821" />
            <inertia ixx="0.02076" ixy="0" ixz="-0.003626" iyy="0.02179" iyz="0" izz="0.00779" />
        </inertial>
        <visual>
            <origin rpy="0 0 0" xyz="0 0 0" />
            <geometry>
                <mesh filename="package://victor_description/meshes/iiwa7/visual/link_2.stl" />
            </geometry>
            <material name="Orange" />
        </visual>
        <collision>
            <origin rpy="0 0 0" xyz="0 0 0" />
            <geometry>
                <mesh filename="package://victor_description/meshes/iiwa7/collision/link_2.stl" />
            </geometry>
            <material name="Orange" />
        </collision>
    </link>
    <joint name="victor_left_arm_joint_3" type="revolute">
        <parent link="victor_left_arm_link_2" />
        <child link="victor_left_arm_link_3" />
        <origin rpy="1.5707963267948966 0 3.141592653589793" xyz="0 0.21 0" />
        <axis xyz="0 0 1" />
        <limit effort="300" lower="-2.9670597283903604" upper="2.9670597283903604" velocity="1.7453292519943295" />
        <dynamics damping="0.5" />
    </joint>
    <link name="victor_left_arm_link_3">
        <inertial>
            <origin rpy="0 0 0" xyz="0 0.03 0.13" />
            <mass value="4.05623" />
            <inertia ixx="0.03204" ixy="0" ixz="0" iyy="0.00972" iyz="0.006227" izz="0.03042" />
        </inertial>
        <visual>
            <origin rpy="0 0 0" xyz="0 0 -0.026" />
            <geometry>
                <mesh filename="package://victor_description/meshes/iiwa7/visual/link_3.stl" />
            </geometry>
            <material name="Orange" />
        </visual>
        <collision>
            <origin rpy="0 0 0" xyz="0 0 -0.026" />
            <geometry>
                <mesh filename="package://victor_description/meshes/iiwa7/collision/link_3.stl" />
            </geometry>
            <material name="Orange" />
        </collision>
    </link>
    <joint name="victor_left_arm_joint_4" type="revolute">
        <parent link="victor_left_arm_link_3" />
        <child link="victor_left_arm_link_4" />
        <origin rpy="1.5707963267948966 0 0" xyz="0 0 0.19" />
        <axis xyz="0 0 1" />
        <limit effort="300" lower="-2.0943951023931953" upper="2.0943951023931953" velocity="2.2689280275926285" />
        <dynamics damping="0.5" />
    </joint>
    <link name="victor_left_arm_link_4">
        <inertial>
            <origin rpy="0 0 0" xyz="0 0.067 0.034" />
            <mass value="3.4822" />
            <inertia ixx="0.02178" ixy="0" ixz="0" iyy="0.02075" iyz="-0.003625" izz="0.007785" />
        </inertial>
        <visual>
            <origin rpy="0 0 0" xyz="0 0 0" />
            <geometry>
                <mesh filename="package://victor_description/meshes/iiwa7/visual/link_4.stl" />
            </geometry>
            <material name="Orange" />
        </visual>
        <collision>
            <origin rpy="0 0 0" xyz="0 0 0" />
            <geometry>
                <mesh filename="package://victor_description/meshes/iiwa7/collision/link_4.stl" />
            </geometry>
            <material name="Orange" />
        </collision>
    </link>
    <joint name="victor_left_arm_joint_5" type="revolute">
        <parent link="victor_left_arm_link_4" />
        <child link="victor_left_arm_link_5" />
        <origin rpy="-1.5707963267948966 3.141592653589793 0" xyz="0 0.21 0" />
        <axis xyz="0 0 1" />
        <limit effort="300" lower="-2.9670597283903604" upper="2.9670597283903604" velocity="2.443460952792061" />
        <dynamics damping="0.5" />
    </joint>
    <link name="victor_left_arm_link_5">
        <inertial>
            <origin rpy="0 0 0" xyz="0.0001 0.021 0.076" />
            <mass value="2.1633" />
            <inertia ixx="0.01287" ixy="0" ixz="0" iyy="0.005708" iyz="-0.003946" izz="0.01112" />
        </inertial>
        <visual>
            <origin rpy="0 0 0" xyz="0 0 -0.026" />
            <geometry>
                <mesh filename="package://victor_description/meshes/iiwa7/visual/link_5.stl" />
            </geometry>
            <material name="Orange" />
        </visual>
        <collision>
            <origin rpy="0 0 0" xyz="0 0 -0.026" />
            <geometry>
                <mesh filename="package://victor_description/meshes/iiwa7/collision/link_5.stl" />
            </geometry>
            <material name="Orange" />
        </collision>
    </link>
    <joint name="victor_left_arm_joint_6" type="revolute">
        <parent link="victor_left_arm_link_5" />
        <child link="victor_left_arm_link_6" />
        <origin rpy="1.5707963267948966 0 0" xyz="0 0.06070 0.19" />
        <axis xyz="0 0 1" />
        <limit effort="300" lower="-2.0943951023931953" upper="2.0943951023931953" velocity="3.141592653589793" />
        <dynamics damping="0.5" />
    </joint>
    <link name="victor_left_arm_link_6">
        <inertial>
            <origin rpy="0 0 0" xyz="0 0.0006 0.0004" />
            <mass value="2.3466" />
            <inertia ixx="0.006509" ixy="0" ixz="0" iyy="0.006259" iyz="0.00031891" izz="0.004527" />
        </inertial>
        <visual>
            <origin rpy="0 0 0" xyz="0 0 0" />
            <geometry>
                <mesh filename="package://victor_description/meshes/iiwa7/visual/link_6.stl" />
            </geometry>
            <material name="Orange" />
        </visual>
        <collision>
            <origin rpy="0 0 0" xyz="0 0 0" />
            <geometry>
                <mesh filename="package://victor_description/meshes/iiwa7/collision/link_6.stl" />
            </geometry>
            <material name="Orange" />
        </collision>
    </link>
    <joint name="victor_left_arm_joint_7" type="revolute">
        <parent link="victor_left_arm_link_6" />
        <child link="victor_left_arm_link_7" />
        <origin rpy="-1.5707963267948966 3.141592653589793 0" xyz="0 0.081 0.06070" />
        <axis xyz="0 0 1" />
        <limit effort="300" lower="-3.0543261909900763" upper="3.0543261909900763" velocity="3.141592653589793" />
        <dynamics damping="0.5" />
    </joint>
    <link name="victor_left_arm_link_7">
        <inertial>
            <origin rpy="0 0 0" xyz="0 0 0.02" />
            <mass value="3.129" />
            <inertia ixx="0.01464" ixy="0.0005912" ixz="0" iyy="0.01465" iyz="0" izz="0.002872" />
        </inertial>
        <visual>
            <origin rpy="0 0 0" xyz="0 0 -0.0005" />
            <geometry>
                <mesh filename="package://victor_description/meshes/iiwa7/visual/link_7_electric.stl" />
            </geometry>
            <material name="Grey" />
        </visual>
        <collision>
            <origin rpy="0 0 0" xyz="0 0 -0.0005" />
            <geometry>
                <mesh filename="package://victor_description/meshes/iiwa7/collision/link_7_electric.stl" />
            </geometry>
            <material name="Grey" />
        </collision>
    </link>
    <joint name="victor_left_arm_joint_flange" type="fixed">
        <parent link="victor_left_arm_link_7" />
        <child link="victor_left_arm_flange" />
        <origin rpy="0 0 0" xyz="0 0 0.045" />
    </joint>
    <link name="victor_left_arm_flange" />
    <!-- Our usage above has been tweaked to match Kuka's internal usage, so identity transform -->
    <joint name="victor_left_arm_flange_kuka_joint" type="fixed">
        <parent link="victor_left_arm_flange" />
        <child link="victor_left_arm_flange_kuka" />
        <origin rpy="0 0 0" xyz="0 0 0" />
    </joint>
    <link name="victor_left_arm_flange_kuka" />
    <!-- Link0 -->
    <gazebo reference="victor_left_arm_link_0">
        <kinematic>0</kinematic>
        <mu1>0.2</mu1>
        <mu2>0.2</mu2>
        <plugin name="gazebo_ros_control">
            <robotNamespace>/</robotNamespace>
        </plugin>
    </gazebo>
    <!-- Link1 -->
    <gazebo reference="victor_left_arm_link_1">
        <kinematic>0</kinematic>
        <mu1>0.2</mu1>
        <mu2>0.2</mu2>
    </gazebo>
    <!-- Link2 -->
    <gazebo reference="victor_left_arm_link_2">
        <kinematic>0</kinematic>
        <mu1>0.2</mu1>
        <mu2>0.2</mu2>
    </gazebo>
    <!-- Link3 -->
    <gazebo reference="victor_left_arm_link_3">
        <kinematic>0</kinematic>
        <mu1>0.2</mu1>
        <mu2>0.2</mu2>
    </gazebo>
    <!-- Link4 -->
    <gazebo reference="victor_left_arm_link_4">
        <kinematic>0</kinematic>
        <mu1>0.2</mu1>
        <mu2>0.2</mu2>
    </gazebo>
    <!-- Link5 -->
    <gazebo reference="victor_left_arm_link_5">
        <kinematic>0</kinematic>
        <mu1>0.2</mu1>
        <mu2>0.2</mu2>
    </gazebo>
    <!-- Link6 -->
    <gazebo reference="victor_left_arm_link_6">
        <kinematic>0</kinematic>
        <mu1>0.2</mu1>
        <mu2>0.2</mu2>
    </gazebo>
    <!-- Link7 -->
    <gazebo reference="victor_left_arm_link_7">
        <kinematic>0</kinematic>
        <mu1>0.2</mu1>
        <mu2>0.2</mu2>
    </gazebo>
    <transmission name="victor_left_arm_tran_1">
        <type>transmission_interface/SimpleTransmission</type>
        <joint name="victor_left_arm_joint_1">
            <hardwareInterface>hardware_interface/EffortJointInterface</hardwareInterface>
        </joint>
        <actuator name="victor_left_arm_motor_1">
            <mechanicalReduction>1</mechanicalReduction>
            <hardwareInterface>hardware_interface/EffortJointInterface</hardwareInterface>
        </actuator>
    </transmission>
    <transmission name="victor_left_arm_tran_2">
        <type>transmission_interface/SimpleTransmission</type>
        <joint name="victor_left_arm_joint_2">
            <hardwareInterface>hardware_interface/EffortJointInterface</hardwareInterface>
        </joint>
        <actuator name="victor_left_arm_motor_2">
            <mechanicalReduction>1</mechanicalReduction>
            <hardwareInterface>hardware_interface/EffortJointInterface</hardwareInterface>
        </actuator>
    </transmission>
    <transmission name="victor_left_arm_tran_3">
        <type>transmission_interface/SimpleTransmission</type>
        <joint name="victor_left_arm_joint_3">
            <hardwareInterface>hardware_interface/EffortJointInterface</hardwareInterface>
        </joint>
        <actuator name="victor_left_arm_motor_3">
            <mechanicalReduction>1</mechanicalReduction>
            <hardwareInterface>hardware_interface/EffortJointInterface</hardwareInterface>
        </actuator>
    </transmission>
    <transmission name="victor_left_arm_tran_4">
        <type>transmission_interface/SimpleTransmission</type>
        <joint name="victor_left_arm_joint_4">
            <hardwareInterface>hardware_interface/EffortJointInterface</hardwareInterface>
        </joint>
        <actuator name="victor_left_arm_motor_4">
            <mechanicalReduction>1</mechanicalReduction>
            <hardwareInterface>hardware_interface/EffortJointInterface</hardwareInterface>
        </actuator>
    </transmission>
    <transmission name="victor_left_arm_tran_5">
        <type>transmission_interface/SimpleTransmission</type>
        <joint name="victor_left_arm_joint_5">
            <hardwareInterface>hardware_interface/EffortJointInterface</hardwareInterface>
        </joint>
        <actuator name="victor_left_arm_motor_5">
            <mechanicalReduction>1</mechanicalReduction>
            <hardwareInterface>hardware_interface/EffortJointInterface</hardwareInterface>
        </actuator>
    </transmission>
    <transmission name="victor_left_arm_tran_6">
        <type>transmission_interface/SimpleTransmission</type>
        <joint name="victor_left_arm_joint_6">
            <hardwareInterface>hardware_interface/EffortJointInterface</hardwareInterface>
        </joint>
        <actuator name="victor_left_arm_motor_6">
            <mechanicalReduction>1</mechanicalReduction>
            <hardwareInterface>hardware_interface/EffortJointInterface</hardwareInterface>
        </actuator>
    </transmission>
    <transmission name="victor_left_arm_tran_7">
        <type>transmission_interface/SimpleTransmission</type>
        <joint name="victor_left_arm_joint_7">
            <hardwareInterface>hardware_interface/EffortJointInterface</hardwareInterface>
        </joint>
        <actuator name="victor_left_arm_motor_7">
            <mechanicalReduction>1</mechanicalReduction>
            <hardwareInterface>hardware_interface/EffortJointInterface</hardwareInterface>
        </actuator>
    </transmission>
    <joint name="victor_joint_left_arm_world_frame_kuka" type="fixed">
        <parent link="victor_left_arm_mount" />
        <child link="victor_left_arm_world_frame_kuka" />
        <origin rpy="1.57079632679 0 0" xyz="0 0 0" />
    </joint>
    <link name="victor_left_arm_world_frame_kuka" />
    <!--joint between {parent} and link_0-->
    <joint name="victor_right_arm_mount_victor_right_arm_joint" type="fixed">
        <origin rpy="0 0 0" xyz="0 0 0" />
        <parent link="victor_right_arm_mount" />
        <child link="victor_right_arm_link_0" />
    </joint>
    <link name="victor_right_arm_link_0">
        <inertial>
            <origin rpy="0 0 0" xyz="-0.1 0 0.07" />
            <mass value="5" />
            <inertia ixx="0.05" ixy="0" ixz="0" iyy="0.06" iyz="0" izz="0.03" />
        </inertial>
        <visual>
            <origin rpy="0 0 0" xyz="0 0 0" />
            <geometry>
                <mesh filename="package://victor_description/meshes/iiwa7/visual/link_0.stl" />
            </geometry>
            <material name="Grey" />
        </visual>
        <collision>
            <origin rpy="0 0 0" xyz="0 0 0" />
            <geometry>
                <mesh filename="package://victor_description/meshes/iiwa7/collision/link_0.stl" />
            </geometry>
            <material name="Grey" />
        </collision>
        <self_collision_checking>
            <origin rpy="0 0 0" xyz="0 0 0" />
            <geometry>
                <capsule length="0.25" radius="0.15" />
            </geometry>
        </self_collision_checking>
    </link>
    <!-- joint between link_0 and link_1 -->
    <joint name="victor_right_arm_joint_1" type="revolute">
        <parent link="victor_right_arm_link_0" />
        <child link="victor_right_arm_link_1" />
        <origin rpy="0 0 0" xyz="0 0 0.15" />
        <axis xyz="0 0 1" />
        <limit effort="300" lower="-2.9670597283903604" upper="2.9670597283903604" velocity="1.7453292519943295" />
        <dynamics damping="0.5" />
    </joint>
    <link name="victor_right_arm_link_1">
        <inertial>
            <origin rpy="0 0 0" xyz="0 -0.03 0.12" />
            <mass value="3.4525" />
            <inertia ixx="0.02183" ixy="0" ixz="0" iyy="0.007703" iyz="-0.003887" izz="0.02083" />
        </inertial>
        <visual>
            <origin rpy="0 0 0" xyz="0 0 0.0075" />
            <geometry>
                <mesh filename="package://victor_description/meshes/iiwa7/visual/link_1.stl" />
            </geometry>
            <material name="Orange" />
        </visual>
        <collision>
            <origin rpy="0 0 0" xyz="0 0 0.0075" />
            <geometry>
                <mesh filename="package://victor_description/meshes/iiwa7/collision/link_1.stl" />
            </geometry>
            <material name="Orange" />
        </collision>
    </link>
    <joint name="victor_right_arm_joint_2" type="revolute">
        <parent link="victor_right_arm_link_1" />
        <child link="victor_right_arm_link_2" />
        <origin rpy="1.5707963267948966   0 3.141592653589793" xyz="0 0 0.19" />
        <axis xyz="0 0 1" />
        <limit effort="300" lower="-2.0943951023931953" upper="2.0943951023931953" velocity="1.7453292519943295" />
        <dynamics damping="0.5" />
    </joint>
    <link name="victor_right_arm_link_2">
        <inertial>
            <origin rpy="0 0 0" xyz="0.0003 0.059 0.042" />
            <mass value="3.4821" />
            <inertia ixx="0.02076" ixy="0" ixz="-0.003626" iyy="0.02179" iyz="0" izz="0.00779" />
        </inertial>
        <visual>
            <origin rpy="0 0 0" xyz="0 0 0" />
            <geometry>
                <mesh filename="package://victor_description/meshes/iiwa7/visual/link_2.stl" />
            </geometry>
            <material name="Orange" />
        </visual>
        <collision>
            <origin rpy="0 0 0" xyz="0 0 0" />
            <geometry>
                <mesh filename="package://victor_description/meshes/iiwa7/collision/link_2.stl" />
            </geometry>
            <material name="Orange" />
        </collision>
    </link>
    <joint name="victor_right_arm_joint_3" type="revolute">
        <parent link="victor_right_arm_link_2" />
        <child link="victor_right_arm_link_3" />
        <origin rpy="1.5707963267948966 0 3.141592653589793" xyz="0 0.21 0" />
        <axis xyz="0 0 1" />
        <limit effort="300" lower="-2.9670597283903604" upper="2.9670597283903604" velocity="1.7453292519943295" />
        <dynamics damping="0.5" />
    </joint>
    <link name="victor_right_arm_link_3">
        <inertial>
            <origin rpy="0 0 0" xyz="0 0.03 0.13" />
            <mass value="4.05623" />
            <inertia ixx="0.03204" ixy="0" ixz="0" iyy="0.00972" iyz="0.006227" izz="0.03042" />
        </inertial>
        <visual>
            <origin rpy="0 0 0" xyz="0 0 -0.026" />
            <geometry>
                <mesh filename="package://victor_description/meshes/iiwa7/visual/link_3.stl" />
            </geometry>
            <material name="Orange" />
        </visual>
        <collision>
            <origin rpy="0 0 0" xyz="0 0 -0.026" />
            <geometry>
                <mesh filename="package://victor_description/meshes/iiwa7/collision/link_3.stl" />
            </geometry>
            <material name="Orange" />
        </collision>
    </link>
    <joint name="victor_right_arm_joint_4" type="revolute">
        <parent link="victor_right_arm_link_3" />
        <child link="victor_right_arm_link_4" />
        <origin rpy="1.5707963267948966 0 0" xyz="0 0 0.19" />
        <axis xyz="0 0 1" />
        <limit effort="300" lower="-2.0943951023931953" upper="2.0943951023931953" velocity="2.2689280275926285" />
        <dynamics damping="0.5" />
    </joint>
    <link name="victor_right_arm_link_4">
        <inertial>
            <origin rpy="0 0 0" xyz="0 0.067 0.034" />
            <mass value="3.4822" />
            <inertia ixx="0.02178" ixy="0" ixz="0" iyy="0.02075" iyz="-0.003625" izz="0.007785" />
        </inertial>
        <visual>
            <origin rpy="0 0 0" xyz="0 0 0" />
            <geometry>
                <mesh filename="package://victor_description/meshes/iiwa7/visual/link_4.stl" />
            </geometry>
            <material name="Orange" />
        </visual>
        <collision>
            <origin rpy="0 0 0" xyz="0 0 0" />
            <geometry>
                <mesh filename="package://victor_description/meshes/iiwa7/collision/link_4.stl" />
            </geometry>
            <material name="Orange" />
        </collision>
    </link>
    <joint name="victor_right_arm_joint_5" type="revolute">
        <parent link="victor_right_arm_link_4" />
        <child link="victor_right_arm_link_5" />
        <origin rpy="-1.5707963267948966 3.141592653589793 0" xyz="0 0.21 0" />
        <axis xyz="0 0 1" />
        <limit effort="300" lower="-2.9670597283903604" upper="2.9670597283903604" velocity="2.443460952792061" />
        <dynamics damping="0.5" />
    </joint>
    <link name="victor_right_arm_link_5">
        <inertial>
            <origin rpy="0 0 0" xyz="0.0001 0.021 0.076" />
            <mass value="2.1633" />
            <inertia ixx="0.01287" ixy="0" ixz="0" iyy="0.005708" iyz="-0.003946" izz="0.01112" />
        </inertial>
        <visual>
            <origin rpy="0 0 0" xyz="0 0 -0.026" />
            <geometry>
                <mesh filename="package://victor_description/meshes/iiwa7/visual/link_5.stl" />
            </geometry>
            <material name="Orange" />
        </visual>
        <collision>
            <origin rpy="0 0 0" xyz="0 0 -0.026" />
            <geometry>
                <mesh filename="package://victor_description/meshes/iiwa7/collision/link_5.stl" />
            </geometry>
            <material name="Orange" />
        </collision>
    </link>
    <joint name="victor_right_arm_joint_6" type="revolute">
        <parent link="victor_right_arm_link_5" />
        <child link="victor_right_arm_link_6" />
        <origin rpy="1.5707963267948966 0 0" xyz="0 0.06070 0.19" />
        <axis xyz="0 0 1" />
        <limit effort="300" lower="-2.0943951023931953" upper="2.0943951023931953" velocity="3.141592653589793" />
        <dynamics damping="0.5" />
    </joint>
    <link name="victor_right_arm_link_6">
        <inertial>
            <origin rpy="0 0 0" xyz="0 0.0006 0.0004" />
            <mass value="2.3466" />
            <inertia ixx="0.006509" ixy="0" ixz="0" iyy="0.006259" iyz="0.00031891" izz="0.004527" />
        </inertial>
        <visual>
            <origin rpy="0 0 0" xyz="0 0 0" />
            <geometry>
                <mesh filename="package://victor_description/meshes/iiwa7/visual/link_6.stl" />
            </geometry>
            <material name="Orange" />
        </visual>
        <collision>
            <origin rpy="0 0 0" xyz="0 0 0" />
            <geometry>
                <mesh filename="package://victor_description/meshes/iiwa7/collision/link_6.stl" />
            </geometry>
            <material name="Orange" />
        </collision>
    </link>
    <joint name="victor_right_arm_joint_7" type="revolute">
        <parent link="victor_right_arm_link_6" />
        <child link="victor_right_arm_link_7" />
        <origin rpy="-1.5707963267948966 3.141592653589793 0" xyz="0 0.081 0.06070" />
        <axis xyz="0 0 1" />
        <limit effort="300" lower="-3.0543261909900763" upper="3.0543261909900763" velocity="3.141592653589793" />
        <dynamics damping="0.5" />
    </joint>
    <link name="victor_right_arm_link_7">
        <inertial>
            <origin rpy="0 0 0" xyz="0 0 0.02" />
            <mass value="3.129" />
            <inertia ixx="0.01464" ixy="0.0005912" ixz="0" iyy="0.01465" iyz="0" izz="0.002872" />
        </inertial>
        <visual>
            <origin rpy="0 0 0" xyz="0 0 -0.0005" />
            <geometry>
                <mesh filename="package://victor_description/meshes/iiwa7/visual/link_7_electric.stl" />
            </geometry>
            <material name="Grey" />
        </visual>
        <collision>
            <origin rpy="0 0 0" xyz="0 0 -0.0005" />
            <geometry>
                <mesh filename="package://victor_description/meshes/iiwa7/collision/link_7_electric.stl" />
            </geometry>
            <material name="Grey" />
        </collision>
    </link>
    <joint name="victor_right_arm_joint_flange" type="fixed">
        <parent link="victor_right_arm_link_7" />
        <child link="victor_right_arm_flange" />
        <origin rpy="0 0 0" xyz="0 0 0.045" />
    </joint>
    <link name="victor_right_arm_flange" />
    <!-- Our usage above has been tweaked to match Kuka's internal usage, so identity transform -->
    <joint name="victor_right_arm_flange_kuka_joint" type="fixed">
        <parent link="victor_right_arm_flange" />
        <child link="victor_right_arm_flange_kuka" />
        <origin rpy="0 0 0" xyz="0 0 0" />
    </joint>
    <link name="victor_right_arm_flange_kuka" />
    <!-- Link0 -->
    <gazebo reference="victor_right_arm_link_0">
        <kinematic>0</kinematic>
        <mu1>0.2</mu1>
        <mu2>0.2</mu2>
    </gazebo>
    <!-- Link1 -->
    <gazebo reference="victor_right_arm_link_1">
        <kinematic>0</kinematic>
        <mu1>0.2</mu1>
        <mu2>0.2</mu2>
    </gazebo>
    <!-- Link2 -->
    <gazebo reference="victor_right_arm_link_2">
        <kinematic>0</kinematic>
        <mu1>0.2</mu1>
        <mu2>0.2</mu2>
    </gazebo>
    <!-- Link3 -->
    <gazebo reference="victor_right_arm_link_3">
        <kinematic>0</kinematic>
        <mu1>0.2</mu1>
        <mu2>0.2</mu2>
    </gazebo>
    <!-- Link4 -->
    <gazebo reference="victor_right_arm_link_4">
        <kinematic>0</kinematic>
        <mu1>0.2</mu1>
        <mu2>0.2</mu2>
    </gazebo>
    <!-- Link5 -->
    <gazebo reference="victor_right_arm_link_5">
        <kinematic>0</kinematic>
        <mu1>0.2</mu1>
        <mu2>0.2</mu2>
    </gazebo>
    <!-- Link6 -->
    <gazebo reference="victor_right_arm_link_6">
        <kinematic>0</kinematic>
        <mu1>0.2</mu1>
        <mu2>0.2</mu2>
    </gazebo>
    <!-- Link7 -->
    <gazebo reference="victor_right_arm_link_7">
        <kinematic>0</kinematic>
        <mu1>0.2</mu1>
        <mu2>0.2</mu2>
    </gazebo>
    <transmission name="victor_right_arm_tran_1">
        <type>transmission_interface/SimpleTransmission</type>
        <joint name="victor_right_arm_joint_1">
            <hardwareInterface>hardware_interface/EffortJointInterface</hardwareInterface>
        </joint>
        <actuator name="victor_right_arm_motor_1">
            <mechanicalReduction>1</mechanicalReduction>
            <hardwareInterface>hardware_interface/EffortJointInterface</hardwareInterface>
        </actuator>
    </transmission>
    <transmission name="victor_right_arm_tran_2">
        <type>transmission_interface/SimpleTransmission</type>
        <joint name="victor_right_arm_joint_2">
            <hardwareInterface>hardware_interface/EffortJointInterface</hardwareInterface>
        </joint>
        <actuator name="victor_right_arm_motor_2">
            <mechanicalReduction>1</mechanicalReduction>
            <hardwareInterface>hardware_interface/EffortJointInterface</hardwareInterface>
        </actuator>
    </transmission>
    <transmission name="victor_right_arm_tran_3">
        <type>transmission_interface/SimpleTransmission</type>
        <joint name="victor_right_arm_joint_3">
            <hardwareInterface>hardware_interface/EffortJointInterface</hardwareInterface>
        </joint>
        <actuator name="victor_right_arm_motor_3">
            <mechanicalReduction>1</mechanicalReduction>
            <hardwareInterface>hardware_interface/EffortJointInterface</hardwareInterface>
        </actuator>
    </transmission>
    <transmission name="victor_right_arm_tran_4">
        <type>transmission_interface/SimpleTransmission</type>
        <joint name="victor_right_arm_joint_4">
            <hardwareInterface>hardware_interface/EffortJointInterface</hardwareInterface>
        </joint>
        <actuator name="victor_right_arm_motor_4">
            <mechanicalReduction>1</mechanicalReduction>
            <hardwareInterface>hardware_interface/EffortJointInterface</hardwareInterface>
        </actuator>
    </transmission>
    <transmission name="victor_right_arm_tran_5">
        <type>transmission_interface/SimpleTransmission</type>
        <joint name="victor_right_arm_joint_5">
            <hardwareInterface>hardware_interface/EffortJointInterface</hardwareInterface>
        </joint>
        <actuator name="victor_right_arm_motor_5">
            <mechanicalReduction>1</mechanicalReduction>
            <hardwareInterface>hardware_interface/EffortJointInterface</hardwareInterface>
        </actuator>
    </transmission>
    <transmission name="victor_right_arm_tran_6">
        <type>transmission_interface/SimpleTransmission</type>
        <joint name="victor_right_arm_joint_6">
            <hardwareInterface>hardware_interface/EffortJointInterface</hardwareInterface>
        </joint>
        <actuator name="victor_right_arm_motor_6">
            <mechanicalReduction>1</mechanicalReduction>
            <hardwareInterface>hardware_interface/EffortJointInterface</hardwareInterface>
        </actuator>
    </transmission>
    <transmission name="victor_right_arm_tran_7">
        <type>transmission_interface/SimpleTransmission</type>
        <joint name="victor_right_arm_joint_7">
            <hardwareInterface>hardware_interface/EffortJointInterface</hardwareInterface>
        </joint>
        <actuator name="victor_right_arm_motor_7">
            <mechanicalReduction>1</mechanicalReduction>
            <hardwareInterface>hardware_interface/EffortJointInterface</hardwareInterface>
        </actuator>
    </transmission>
    <joint name="victor_joint_right_arm_world_frame_kuka" type="fixed">
        <parent link="victor_right_arm_mount" />
        <child link="victor_right_arm_world_frame_kuka" />
        <origin rpy="-1.57079632679 0 0" xyz="0 0 0" />
    </joint>
    <link name="victor_right_arm_world_frame_kuka" />
    <!--joint between {parent} and link_0-->
    <joint name="victor_left_arm_flange_victor_left_joint" type="fixed">
        <origin rpy="0 0 0" xyz="0 0 -0.01" />
        <parent link="victor_left_arm_flange" />
        <child link="victor_left_gripper_mounting_bracket" />
    </joint>
    <link name="victor_left_gripper_mounting_bracket">
        <visual>
            <origin rpy="0 0 0" xyz="0 0 0" />
            <geometry>
                <mesh filename="package://victor_description/meshes/robotiq_3finger/kuka_to_palm_connectors_visual.stl" />
            </geometry>
            <material name="LightGrey" />
        </visual>
        <collision>
            <origin rpy="0 0 0" xyz="0 0 0" />
            <geometry>
                <mesh filename="package://victor_description/meshes/robotiq_3finger/kuka_to_palm_connectors_collision.stl" />
            </geometry>
            <material name="LightGrey" />
        </collision>
        <inertial>
            <mass value="0.1" />
            <origin xyz="0 0 0" rpy="0 0 0" />
            <inertia ixx="0.03" iyy="0.03" izz="0.03" ixy="0.0" ixz="0.0" iyz="0.0" />
        </inertial>
    </link>
    <!--joint between {parent} and link_0-->
    <joint name="victor_right_arm_flange_victor_right_joint" type="fixed">
        <origin rpy="0 0 0" xyz="0 0 -0.01" />
        <parent link="victor_right_arm_flange" />
        <child link="victor_right_gripper_mounting_bracket" />
    </joint>
    <link name="victor_right_gripper_mounting_bracket">
        <visual>
            <origin rpy="0 0 0" xyz="0 0 0" />
            <geometry>
                <mesh filename="package://victor_description/meshes/robotiq_3finger/kuka_to_palm_connectors_visual.stl" />
            </geometry>
            <material name="LightGrey" />
        </visual>
        <collision>
            <origin rpy="0 0 0" xyz="0 0 0" />
            <geometry>
                <mesh filename="package://victor_description/meshes/robotiq_3finger/kuka_to_palm_connectors_collision.stl" />
            </geometry>
            <material name="LightGrey" />
        </collision>
        <inertial>
            <mass value="0.1" />
            <origin xyz="0 0 0" rpy="0 0 0" />
            <inertia ixx="0.03" iyy="0.03" izz="0.03" ixy="0.0" ixz="0.0" iyz="0.0" />
        </inertial>
    </link>
    <link name="left_tool">
        <visual name="left_tool_visual">
            <origin rpy="0 0 0" xyz="0 0 0" />
            <geometry>
                <sphere radius="0.002" />
            </geometry>
        </visual>
        <inertial>
            <origin rpy="0 0 0" xyz="0 0 0" />
            <!-- It's important that these have non-zero mass, otherwise gazebos URDF to SDF conversion will ignore them -->
            <mass value="0.001" />
            <inertia ixx="0" ixy="0" ixz="0" iyy="0" iyz="0" izz="0" />
        </inertial>
    </link>
    <joint name="left_tool_joint" type="fixed">
        <parent link="victor_left_arm_link_7" />
        <child link="left_tool" />
        <origin xyz="0 0 0.254" />
    </joint>
    <link name="right_tool">
        <visual name="right_tool_visual">
            <origin rpy="0 0 0" xyz="0 0 0" />
            <geometry>
                <sphere radius="0.002" />
            </geometry>
        </visual>
        <inertial>
            <origin rpy="0 0 0" xyz="0 0 0" />
            <mass value="0.001" />
            <inertia ixx="0" ixy="0" ixz="0" iyy="0" iyz="0" izz="0" />
        </inertial>
    </link>
    <joint name="right_tool_joint" type="fixed">
        <parent link="victor_right_arm_link_7" />
        <child link="right_tool" />
        <origin xyz="0 0 0.254" />
    </joint>
    <gazebo reference="victor_pedestal">
        <visual>
            <material>
                <diffuse>0.2 0.2 0.2 1.0</diffuse>
                <ambient>0.1 0.1 0.1 1.0</ambient>
            </material>
        </visual>
    </gazebo>
    <gazebo reference="victor_base_plate">
        <visual>
            <material>
                <diffuse>0.7 0.7 0.7 1.0</diffuse>
                <ambient>0.3 0.3 0.3 1.0</ambient>
                <specular>0.9 0.9 0.9 1.0</specular>
            </material>
        </visual>
    </gazebo>
    <gazebo reference="right_tool_joint">
        <preserveFixedJoint>true</preserveFixedJoint>
    </gazebo>
    <gazebo reference="left_tool_joint">
        <preserveFixedJoint>true</preserveFixedJoint>
    </gazebo>
    <gazebo>
        <plugin filename="libgazebo_ros_control.so" name="gazebo_ros_control">
            <robotNamespace>victor</robotNamespace>
            <legacyModeNS>false</legacyModeNS>
        </plugin>
    </gazebo>
    <gazebo>
        <plugin filename="libgazebo_ros_moveit_planning_scene.so" name="gazebo_ros_moveit_planning_scene">
            <robotName>victor</robotName>
            <robotNamespace>victor</robotNamespace>
            <!--  This must be the same as the root frame of the robot you're using -->
            <frameId>victor_root</frameId>
            <excludedModels>collision_sphere</excludedModels>
            <scalePrimitivesFactor>1.1</scalePrimitivesFactor>
        </plugin>
    </gazebo>
    <link name="world" />
    <joint name="world_joint" type="fixed">
        <parent link="world" />
        <child link="victor_root" />
        <origin rpy="0.0 0.0 0.0" xyz="0.0 0.0 0.0" />
    </joint>
</robot>

